{
    DataVersion: 3465,
    size: [8, 13, 8],
    data: [
        {pos: [4, 1, 3], state: "minecraft:lantern{hanging:true,waterlogged:false}"},
        {pos: [3, 2, 2], state: "minecraft:bedrock"},
        {pos: [3, 2, 3], state: "minecraft:oak_stairs{facing:east,half:top,shape:straight,waterlogged:false}"},
        {pos: [3, 2, 4], state: "minecraft:bedrock"},
        {pos: [4, 2, 2], state: "minecraft:oak_stairs{facing:south,half:top,shape:straight,waterlogged:false}"},
        {pos: [4, 2, 3], state: "minecraft:bedrock"},
        {pos: [4, 2, 4], state: "minecraft:oak_stairs{facing:north,half:top,shape:straight,waterlogged:false}"},
        {pos: [5, 2, 2], state: "minecraft:bedrock"},
        {pos: [5, 2, 3], state: "minecraft:oak_stairs{facing:west,half:top,shape:straight,waterlogged:false}"},
        {pos: [5, 2, 4], state: "minecraft:bedrock"},
        {pos: [3, 3, 2], state: "minecraft:grass_block{snowy:false}"},
        {pos: [3, 3, 3], state: "minecraft:grass_block{snowy:false}"},
        {pos: [3, 3, 4], state: "minecraft:grass_block{snowy:false}"},
        {pos: [4, 3, 2], state: "minecraft:grass_block{snowy:false}"},
        {pos: [4, 3, 3], state: "minecraft:dirt"},
        {pos: [4, 3, 4], state: "minecraft:grass_block{snowy:false}"},
        {pos: [5, 3, 2], state: "minecraft:grass_block{snowy:false}"},
        {pos: [5, 3, 3], state: "minecraft:grass_block{snowy:false}"},
        {pos: [5, 3, 4], state: "minecraft:grass_block{snowy:false}"},
        {pos: [4, 4, 3], state: "minecraft:oak_log{axis:y}"},
        {pos: [4, 5, 3], state: "minecraft:oak_log{axis:y}"},
        {pos: [2, 6, 2], state: "minecraft:oak_leaves{distance:3,persistent:false,waterlogged:false}"},
        {pos: [2, 6, 3], state: "minecraft:oak_leaves{distance:2,persistent:false,waterlogged:false}"},
        {pos: [2, 6, 4], state: "minecraft:oak_leaves{distance:3,persistent:false,waterlogged:false}"},
        {pos: [2, 6, 5], state: "minecraft:oak_leaves{distance:4,persistent:false,waterlogged:false}"},
        {pos: [3, 6, 1], state: "minecraft:oak_leaves{distance:3,persistent:false,waterlogged:false}"},
        {pos: [3, 6, 2], state: "minecraft:oak_leaves{distance:2,persistent:false,waterlogged:false}"},
        {pos: [3, 6, 3], state: "minecraft:oak_leaves{distance:1,persistent:false,waterlogged:false}"},
        {pos: [3, 6, 4], state: "minecraft:oak_leaves{distance:2,persistent:false,waterlogged:false}"},
        {pos: [3, 6, 5], state: "minecraft:oak_leaves{distance:3,persistent:false,waterlogged:false}"},
        {pos: [4, 6, 1], state: "minecraft:oak_leaves{distance:2,persistent:false,waterlogged:false}"},
        {pos: [4, 6, 2], state: "minecraft:oak_leaves{distance:1,persistent:false,waterlogged:false}"},
        {pos: [4, 6, 3], state: "minecraft:oak_log{axis:y}"},
        {pos: [4, 6, 4], state: "minecraft:oak_leaves{distance:1,persistent:false,waterlogged:false}"},
        {pos: [4, 6, 5], state: "minecraft:oak_leaves{distance:2,persistent:false,waterlogged:false}"},
        {pos: [5, 6, 1], state: "minecraft:oak_leaves{distance:3,persistent:false,waterlogged:false}"},
        {pos: [5, 6, 2], state: "minecraft:oak_leaves{distance:2,persistent:false,waterlogged:false}"},
        {pos: [5, 6, 3], state: "minecraft:oak_leaves{distance:1,persistent:false,waterlogged:false}"},
        {pos: [5, 6, 4], state: "minecraft:oak_leaves{distance:2,persistent:false,waterlogged:false}"},
        {pos: [5, 6, 5], state: "minecraft:oak_leaves{distance:3,persistent:false,waterlogged:false}"},
        {pos: [6, 6, 2], state: "minecraft:oak_leaves{distance:3,persistent:false,waterlogged:false}"},
        {pos: [6, 6, 3], state: "minecraft:oak_leaves{distance:2,persistent:false,waterlogged:false}"},
        {pos: [6, 6, 4], state: "minecraft:oak_leaves{distance:3,persistent:false,waterlogged:false}"},
        {pos: [6, 6, 5], state: "minecraft:oak_leaves{distance:4,persistent:false,waterlogged:false}"},
        {pos: [2, 7, 1], state: "minecraft:oak_leaves{distance:4,persistent:false,waterlogged:false}"},
        {pos: [2, 7, 2], state: "minecraft:oak_leaves{distance:3,persistent:false,waterlogged:false}"},
        {pos: [2, 7, 3], state: "minecraft:oak_leaves{distance:2,persistent:false,waterlogged:false}"},
        {pos: [2, 7, 4], state: "minecraft:oak_leaves{distance:3,persistent:false,waterlogged:false}"},
        {pos: [2, 7, 5], state: "minecraft:oak_leaves{distance:4,persistent:false,waterlogged:false}"},
        {pos: [3, 7, 1], state: "minecraft:oak_leaves{distance:3,persistent:false,waterlogged:false}"},
        {pos: [3, 7, 2], state: "minecraft:oak_leaves{distance:2,persistent:false,waterlogged:false}"},
        {pos: [3, 7, 3], state: "minecraft:oak_leaves{distance:1,persistent:false,waterlogged:false}"},
        {pos: [3, 7, 4], state: "minecraft:oak_leaves{distance:2,persistent:false,waterlogged:false}"},
        {pos: [3, 7, 5], state: "minecraft:oak_leaves{distance:3,persistent:false,waterlogged:false}"},
        {pos: [4, 7, 1], state: "minecraft:oak_leaves{distance:2,persistent:false,waterlogged:false}"},
        {pos: [4, 7, 2], state: "minecraft:oak_leaves{distance:1,persistent:false,waterlogged:false}"},
        {pos: [4, 7, 3], state: "minecraft:oak_log{axis:y}"},
        {pos: [4, 7, 4], state: "minecraft:oak_leaves{distance:1,persistent:false,waterlogged:false}"},
        {pos: [4, 7, 5], state: "minecraft:oak_leaves{distance:2,persistent:false,waterlogged:false}"},
        {pos: [5, 7, 1], state: "minecraft:oak_leaves{distance:3,persistent:false,waterlogged:false}"},
        {pos: [5, 7, 2], state: "minecraft:oak_leaves{distance:2,persistent:false,waterlogged:false}"},
        {pos: [5, 7, 3], state: "minecraft:oak_leaves{distance:1,persistent:false,waterlogged:false}"},
        {pos: [5, 7, 4], state: "minecraft:oak_leaves{distance:2,persistent:false,waterlogged:false}"},
        {pos: [5, 7, 5], state: "minecraft:oak_leaves{distance:3,persistent:false,waterlogged:false}"},
        {pos: [6, 7, 1], state: "minecraft:oak_leaves{distance:4,persistent:false,waterlogged:false}"},
        {pos: [6, 7, 2], state: "minecraft:oak_leaves{distance:3,persistent:false,waterlogged:false}"},
        {pos: [6, 7, 3], state: "minecraft:oak_leaves{distance:2,persistent:false,waterlogged:false}"},
        {pos: [6, 7, 4], state: "minecraft:oak_leaves{distance:3,persistent:false,waterlogged:false}"},
        {pos: [3, 8, 2], state: "minecraft:oak_leaves{distance:2,persistent:false,waterlogged:false}"},
        {pos: [3, 8, 3], state: "minecraft:oak_leaves{distance:1,persistent:false,waterlogged:false}"},
        {pos: [3, 8, 4], state: "minecraft:oak_leaves{distance:2,persistent:false,waterlogged:false}"},
        {pos: [4, 8, 2], state: "minecraft:oak_leaves{distance:1,persistent:false,waterlogged:false}"},
        {pos: [4, 8, 3], state: "minecraft:oak_log{axis:y}"},
        {pos: [4, 8, 4], state: "minecraft:oak_leaves{distance:1,persistent:false,waterlogged:false}"},
        {pos: [5, 8, 2], state: "minecraft:oak_leaves{distance:2,persistent:false,waterlogged:false}"},
        {pos: [5, 8, 3], state: "minecraft:oak_leaves{distance:1,persistent:false,waterlogged:false}"},
        {pos: [3, 9, 3], state: "minecraft:oak_leaves{distance:2,persistent:false,waterlogged:false}"},
        {pos: [4, 9, 2], state: "minecraft:oak_leaves{distance:2,persistent:false,waterlogged:false}"},
        {pos: [4, 9, 3], state: "minecraft:oak_leaves{distance:1,persistent:false,waterlogged:false}"},
        {pos: [4, 9, 4], state: "minecraft:oak_leaves{distance:2,persistent:false,waterlogged:false}"},
        {pos: [5, 9, 3], state: "minecraft:oak_leaves{distance:2,persistent:false,waterlogged:false}"}
    ],
    entities: [],
    palette: [
        "minecraft:bedrock",
        "minecraft:grass_block{snowy:false}",
        "minecraft:dirt",
        "minecraft:oak_log{axis:y}",
        "minecraft:oak_leaves{distance:3,persistent:false,waterlogged:false}",
        "minecraft:oak_leaves{distance:2,persistent:false,waterlogged:false}",
        "minecraft:oak_leaves{distance:4,persistent:false,waterlogged:false}",
        "minecraft:oak_leaves{distance:1,persistent:false,waterlogged:false}",
        "minecraft:lantern{hanging:true,waterlogged:false}",
        "minecraft:oak_stairs{facing:east,half:top,shape:straight,waterlogged:false}",
        "minecraft:oak_stairs{facing:south,half:top,shape:straight,waterlogged:false}",
        "minecraft:oak_stairs{facing:north,half:top,shape:straight,waterlogged:false}",
        "minecraft:oak_stairs{facing:west,half:top,shape:straight,waterlogged:false}"
    ]
}